Workbook

Sheet Leia_Me
A1: Previsão de ligações ao 190 (Fortaleza-CE) — instância para Prophet
A3: Contexto | B3: Série diária do volume de ligações ao 190 classificadas em três grupos de intercorrência: crimes contra a vida, crimes contra o patrimônio e perturbação da ordem pública, em Fortaleza, Ceará.
A4: Período | B4: 01/01/2023 a 31/12/2025 (1.096 observações diárias por categoria).
A5: Aba recomendada | B5: Serie_Diaria (uma linha por dia) ou Dados_Longos (formato ds/y por categoria, pronto para o Prophet). A aba Feriados já está no formato exigido pelo parâmetro holidays do Prophet.
A6: AVISO | B6: Os dados não representam estatísticas oficiais da SSPDS-CE, da CIOPS nem de qualquer órgão.
A7: Legenda de cores | B7: Fundo amarelo claro = período de teste. Texto azul = parâmetros de entrada (aba Painel). Texto preto = fórmulas e dados.
A8: Abas | B8: Leia_Me · Serie_Diaria · Dados_Longos · Feriados · Dicionario · Painel

Sheet Serie_Diaria
A1: Data | B1: Dia_Semana | C1: Crimes_Vida | D1: Crimes_Patrimonio | E1: Perturbacao_Ordem | F1: Total_Ligacoes | G1: Feriado | H1: Nome_Feriado | I1: Dia_Pagamento | J1: Chuva_mm
A2: 44927 | B2: Domingo | C2: 21 | D2: 102 | E2: 355 | F2: =SUM(C2:E2) -> 478 | G2: 1 | H2: Confraternizacao Universal | I2: 0 | J2: 0
A3: 44928 | B3: Segunda-feira | C3: 24 | D3: 160 | E3: 211 | F3: =SUM(C3:E3) -> 395 | G3: 0 | I3: 0 | J3: 4.4
A4: 44929 | B4: Terça-feira | C4: 21 | D4: 148 | E4: 197 | F4: =SUM(C4:E4) -> 366 | G4: 0 | I4: 0 | J4: 0
A5: 44930 | B5: Quarta-feira | C5: 19 | D5: 170 | E5: 165 | F5: =SUM(C5:E5) -> 354 | G5: 0 | I5: 0 | J5: 0
A6: 44931 | B6: Quinta-feira | C6: 18 | D6: 126 | E6: 269 | F6: =SUM(C6:E6) -> 413 | G6: 0 | I6: 1 | J6: 0
A7: 44932 | B7: Sexta-feira | C7: 20 | D7: 245 | E7: 331 | F7: =SUM(C7:E7) -> 596 | G7: 0 | I7: 1 | J7: 1.4
A8: 44933 | B8: Sábado | C8: 29 | D8: 185 | E8: 353 | F8: =SUM(C8:E8) -> 567 | G8: 0 | I8: 1 | J8: 0
A9: 44934 | B9: Domingo | C9: 22 | D9: 117 | E9: 252 | F9: =SUM(C9:E9) -> 391 | G9: 0 | I9: 0 | J9: 0
A10: 44935 | B10: Segunda-feira | C10: 8 | D10: 187 | E10: 209 | F10: =SUM(C10:E10) -> 404 | G10: 0 | I10: 0 | J10: 0
A11: 44936 | B11: Terça-feira | C11: 13 | D11: 160 | E11: 214 | F11: =SUM(C11:E11) -> 387 | G11: 0 | I11: 0 | J11: 0
A12: 44937 | B12: Quarta-feira | C12: 23 | D12: 138 | E12: 232 | F12: =SUM(C12:E12) -> 393 | G12: 0 | I12: 0 | J12: 30.3
A13: 44938 | B13: Quinta-feira | C13: 17 | D13: 151 | E13: 231 | F13: =SUM(C13:E13) -> 399 | G13: 0 | I13: 0 | J13: 38.4
A14: 44939 | B14: Sexta-feira | C14: 18 | D14: 180 | E14: 271 | F14: =SUM(C14:E14) -> 469 | G14: 0 | I14: 0 | J14: 0
... A50: 44975 | B50: Sábado | C50: 24 | D50: 145 | E50: 275 | F50: =SUM(C50:E50) -> 444 | G50: 0 | I50: 0 | J50: 0
A51: 44976 | B51: Domingo | C51: 30 | D51: 102 | E51: 307 | F51: =SUM(C51:E51) -> 439 | G51: 1 | H51: Carnaval | I51: 0 | J51: 20.2
A52: 44977 | B52: Segunda-feira | C52: 24 | D52: 140 | E52: 332 | F52: =SUM(C52:E52) -> 496 | G52: 1 | H52: Carnaval | I52: 0 | J52: 16.7
A53: 44978 | B53: Terça-feira | C53: 30 | D53: 132 | E53: 295 | F53: =SUM(C53:E53) -> 457 | G53: 1 | H53: Carnaval | I53: 0 | J53: 10.5
A54: 44979 | B54: Quarta-feira | C54: 16 | D54: 117 | E54: 328 | F54: =SUM(C54:E54) -> 461 | G54: 1 | H54: Carnaval | I54: 0 | J54: 5.9
A55: 44980 | B55: Quinta-feira | C55: 22 | D55: 113 | E55: 184 | F55: =SUM(C55:E55) -> 319 | G55: 0 | I55: 0 | J55: 14.9
A56: 44981 | B56: Sexta-feira | C56: 24 | D56: 152 | E56: 298 | F56: =SUM(C56:E56) -> 474 | G56: 0 | I56: 0 | J56: 0
A57: 44982 | B57: Sábado | C57: 18 | D57: 192 | E57: 291 | F57: =SUM(C57:E57) -> 501 | G57: 0 | I57: 0 | J57: 0
A58: 44983 | B58: Domingo | C58: 25 | D58: 157 | E58: 295 | F58: =SUM(C58:E58) -> 477 | G58: 0 | I58: 0 | J58: 4.2
A59: 44984 | B59: Segunda-feira | C59: 23 | D59: 185 | E59: 213 | F59: =SUM(C59:E59) -> 421 | G59: 0 | I59: 0 | J59: 7.8
A60: 44985 | B60: Terça-feira | C60: 17 | D60: 119 | E60: 216 | F60: =SUM(C60:E60) -> 352 | G60: 0 | I60: 0 | J60: 0
A61: 44986 | B61: Quarta-feira | C61: 13 | D61: 147 | E61: 196 | F61: =SUM(C61:E61) -> 356 | G61: 0 | I61: 0 | J61: 14.1
A62: 44987 | B62: Quinta-feira | C62: 21 | D62: 158 | E62: 270 | F62: =SUM(C62:E62) -> 449 | G62: 0 | I62: 0 | J62: 0
A63: 44988 | B63: Sexta-feira | C63: 22 | D63: 143 | E63: 233 | F63: =SUM(C63:E63) -> 398 | G63: 0 | I63: 0 | J63: 18.5
A64: 44989 | B64: Sábado | C64: 29 | D64: 148 | E64: 277 | F64: =SUM(C64:E64) -> 454 | G64: 0 | I64: 0 | J64: 0
A65: 44990 | B65: Domingo | C65: 21 | D65: 143 | E65: 338 | F65: =SUM(C65:E65) -> 502 | G65: 0 | I65: 1 | J65: 7
A66: 44991 | B66: Segunda-feira | C66: 19 | D66: 173 | E66: 165 | F66: =SUM(C66:E66) -> 357 | G66: 0 | I66: 1 | J66: 0
... A78: 45003 | B78: Sábado | C78: 25 | D78: 123 | E78: 318 | F78: =SUM(C78:E78) -> 466 | G78: 0 | I78: 0 | J78: 33.1
A79: 45004 | B79: Domingo | C79: 24 | D79: 103 | E79: 301 | F79: =SUM(C79:E79) -> 428 | G79: 1 | H79: Sao Jose (Ceara) | I79: 0 | J79: 0
A80: 45005 | B80: Segunda-feira | C80: 16 | D80: 133 | E80: 195 | F80: =SUM(C80:E80) -> 344 | G80: 0 | I80: 0 | J80: 0
A81: 45006 | B81: Terça-feira | C81: 15 | D81: 155 | E81: 195 | F81: =SUM(C81:E81) -> 365 | G81: 0 | I81: 0 | J81: 0
A82: 45007 | B82: Quarta-feira | C82: 30 | D82: 149 | E82: 219 | F82: =SUM(C82:E82) -> 398 | G82: 0 | I82: 0 | J82: 36.3
A83: 45008 | B83: Quinta-feira | C83: 21 | D83: 136 | E83: 222 | F83: =SUM(C83:E83) -> 379 | G83: 0 | I83: 0 | J83: 16.3
A84: 45009 | B84: Sexta-feira | C84: 29 | D84: 159 | E84: 244 | F84: =SUM(C84:E84) -> 432 | G84: 0 | I84: 0 | J84: 0
A85: 45010 | B85: Sábado | C85: 25 | D85: 142 | E85: 372 | F85: =SUM(C85:E85) -> 539 | G85: 1 | H85: Data Magna do Ceara | I85: 0 | J85: 0
A86: 45011 | B86: Domingo | C86: 16 | D86: 131 | E86: 277 | F86: =SUM(C86:E86) -> 424 | G86: 0 | I86: 0 | J86: 28.4
...

Sheet Dados_Longos
A1: ds | B1: y | C1: categoria
A2: 44927 | B2: 21 | C2: Crimes contra a vida
A3: 44928 | B3: 24 | C3: Crimes contra a vida
A4: 44929 | B4: 21 | C4: Crimes contra a vida
A5: 44930 | B5: 19 | C5: Crimes contra a vida
A6: 44931 | B6: 18 | C6: Crimes contra a vida
A7: 44932 | B7: 20 | C7: Crimes contra a vida
A8: 44933 | B8: 29 | C8: Crimes contra a vida
A9: 44934 | B9: 22 | C9: Crimes contra a vida
A10: 44935 | B10: 8 | C10: Crimes contra a vida
A11: 44936 | B11: 13 | C11: Crimes contra a vida
A12: 44937 | B12: 23 | C12: Crimes contra a vida
A13: 44938 | B13: 17 | C13: Crimes contra a vida
... A3289: 46022 | B3289: 399 | C3289: Perturbacao da ordem publica

Sheet Feriados
A1: holiday | B1: ds | C1: lower_window | D1: upper_window | E1: tipo
A2: Confraternizacao Universal | B2: 44927 | C2: 0 | D2: 0 | E2: Nacional
A3: Carnaval | B3: 44976 | C3: 0 | D3: 3 | E3: Facultativo
A4: Sao Jose (Ceara) | B4: 45004 | C4: 0 | D4: 0 | E4: Estadual
A5: Data Magna do Ceara | B5: 45010 | C5: 0 | D5: 0 | E5: Estadual
A6: Sexta-feira Santa | B6: 45023 | C6: 0 | D6: 0 | E6: Nacional
A7: Tiradentes | B7: 45037 | C7: 0 | D7: 0 | E7: Nacional
A8: Dia do Trabalho | B8: 45047 | C8: 0 | D8: 0 | E8: Nacional
A9: Dia das Maes | B9: 45060 | C9: 0 | D9: 0 | E9: Data comemorativa
A10: Corpus Christi | B10: 45085 | C10: 0 | D10: 0 | E10: Facultativo
A11: Dia dos Pais | B11: 45151 | C11: 0 | D11: 0 | E11: Data comemorativa
A12: Assuncao de N. Sra. (Fortaleza) | B12: 45153 | C12: 0 | D12: 0 | E12: Municipal
A13: Independencia | B13: 45176 | C13: 0 | D13: 0 | E13: Nacional
... A76: Reveillon | B76: 46387 | C76: 0 | D76: 1 | E76: Data comemorativa
A78: Nota: datas por regra de calendário (2023-2026), para uso pedagógico. Confirme decretos oficiais antes de uso operacional. Carnaval: ds = sábado, upper_window = 3 (até a terça-feira). Réveillon: upper_window = 1 (inclui 01/01). Use apenas as 4 primeiras colunas no Prophet.

Sheet Dicionario
A1: Campo | B1: Aba | C1: Descrição | D1: Uso no Prophet
A2: Data / ds | B2: Serie_Diaria / Dados_Longos | C2: Data do dia (frequência diária). | D2: Coluna ds.
A3: Dia_Semana | B3: Serie_Diaria | C3: Nome do dia da semana. | D3: Apenas apoio à análise; o Prophet deriva a sazonalidade semanal de ds.
A4: Crimes_Vida | B4: Serie_Diaria | C4: Ligações ao 190 classificadas como crimes contra a vida (ex.: homicídio e tentativa, disparos de arma de fogo, ameaça grave à vida). | D4: Alvo y (categoria 1).
A5: Crimes_Patrimonio | B5: Serie_Diaria | C5: Ligações classificadas como crimes contra o patrimônio (ex.: roubo, furto, dano a bem). | D5: Alvo y (categoria 2).
A6: Perturbacao_Ordem | B6: Serie_Diaria | C6: Ligações classificadas como perturbação da ordem pública (ex.: som alto, brigas e desordem, aglomerações). | D6: Alvo y (categoria 3).
A7: Total_Ligacoes | B7: Serie_Diaria | C7: Soma das três categorias (fórmula). | D7: Pode ser modelado como quarta série agregada.
A8: Feriado | B8: Serie_Diaria | C8: 1 se o dia é feriado/data especial (inclui janelas da aba Feriados). | D8: Alternativa binária ao DataFrame holidays.
A9: Nome_Feriado | B9: Serie_Diaria | C9: Nome do feriado ou data comemorativa. | D9: —
A10: Dia_Pagamento | B10: Serie_Diaria | C10: 1 entre os dias 5 e 7 do mês (proxy de pagamento de salários). | D10: Regressor externo conhecido no futuro: add_regressor('Dia_Pagamento').
A11: Chuva_mm | B11: Serie_Diaria | C11: Precipitação diária sintética (mm), com estação chuvosa de fevereiro a maio. | D11: Regressor externo NÃO conhecido no futuro: exige previsão ou climatologia.
A12: categoria | B12: Dados_Longos | C12: Nome da categoria em formato longo. | D12: Laço de ajuste: um modelo por categoria.
... A15: Limitações | B15: — | C15: Sem georreferenciamento; sem separação por área integrada de segurança; sem registro de ligações não procedentes (trotes). | D15: —

Sheet Painel
A1: Painel — estatísticas descritivas (fórmulas ligadas à aba Serie_Diaria)
A3: Categoria | B3: Média (lig./dia) | C3: Mínimo diário | D3: Máximo diário | E3: Desvio-padrão | F3: Total no período
A4: Crimes contra a vida | B4: =AVERAGE(Serie_Diaria!C2:C1097) -> 18.798358 | C4: =MIN(Serie_Diaria!C2:C1097) -> 5 | D4: =MAX(Serie_Diaria!C2:C1097) -> 39 | E4: =STDEV(Serie_Diaria!C2:C1097) -> 5.4025562 | F4: =SUM(Serie_Diaria!C2:C1097) -> 20603
A5: Crimes contra o patrimônio | B5: =AVERAGE(Serie_Diaria!D2:D1097) -> 141.07026 | C5: =MIN(Serie_Diaria!D2:D1097) -> 72 | D5: =MAX(Serie_Diaria!D2:D1097) -> 245 | E5: =STDEV(Serie_Diaria!D2:D1097) -> 26.306476 | F5: =SUM(Serie_Diaria!D2:D1097) -> 154613
A6: Perturbação da ordem pública | B6: =AVERAGE(Serie_Diaria!E2:E1097) -> 258.56843 | C6: =MIN(Serie_Diaria!E2:E1097) -> 127 | D6: =MAX(Serie_Diaria!E2:E1097) -> 478 | E6: =STDEV(Serie_Diaria!E2:E1097) -> 62.546895 | F6: =SUM(Serie_Diaria!E2:E1097) -> 283391
A7: Total de ligações | B7: =AVERAGE(Serie_Diaria!F2:F1097) -> 418.43704 | C7: =MIN(Serie_Diaria!F2:F1097) -> 260 | D7: =MAX(Serie_Diaria!F2:F1097) -> 648 | E7: =STDEV(Serie_Diaria!F2:F1097) -> 69.842639 | F7: =SUM(Serie_Diaria!F2:F1097) -> 458607
A10: Média por dia da semana (apenas treino)
A11: Dia da semana | B11: Vida | C11: Patrimônio | D11: Ordem pública | E11: Total
A12: Segunda-feira | B12: =AVERAGEIFS(Serie_Diaria!C$2:C$1097,Serie_Diaria!$B$2:$B$1097,$A12) -> 17.229299 | C12: =AVERAGEIFS(Serie_Diaria!D$2:D$1097,Serie_Diaria!$B$2:$B$1097,$A12) -> 143.26752 | D12: =AVERAGEIFS(Serie_Diaria!E$2:E$1097,Serie_Diaria!$B$2:$B$1097,$A12) -> 221.7707 | E12: =AVERAGEIFS(Serie_Diaria!F$2:F$1097,Serie_Diaria!$B$2:$B$1097,$A12) -> 382.26752
A13: Terça-feira | B13: =AVERAGEIFS(Serie_Diaria!C$2:C$1097,Serie_Diaria!$B$2:$B$1097,$A13) -> 17.012739 | C13: =AVERAGEIFS(Serie_Diaria!D$2:D$1097,Serie_Diaria!$B$2:$B$1097,$A13) -> 141.25478 | D13: =AVERAGEIFS(Serie_Diaria!E$2:E$1097,Serie_Diaria!$B$2:$B$1097,$A13) -> 209.03822 | E13: =AVERAGEIFS(Serie_Diaria!F$2:F$1097,Serie_Diaria!$B$2:$B$1097,$A13) -> 367.30573
A14: Quarta-feira | B14: =AVERAGEIFS(Serie_Diaria!C$2:C$1097,Serie_Diaria!$B$2:$B$1097,$A14) -> 17.133758 | C14: =AVERAGEIFS(Serie_Diaria!D$2:D$1097,Serie_Diaria!$B$2:$B$1097,$A14) -> 140.73248 | D14: =AVERAGEIFS(Serie_Diaria!E$2:E$1097,Serie_Diaria!$B$2:$B$1097,$A14) -> 220.72611 | E14: =AVERAGEIFS(Serie_Diaria!F$2:F$1097,Serie_Diaria!$B$2:$B$1097,$A14) -> 378.59236
A15: Quinta-feira | B15: =AVERAGEIFS(Serie_Diaria!C$2:C$1097,Serie_Diaria!$B$2:$B$1097,$A15) -> 17.544872 | C15: =AVERAGEIFS(Serie_Diaria!D$2:D$1097,Serie_Diaria!$B$2:$B$1097,$A15) -> 143.8141 | D15: =AVERAGEIFS(Serie_Diaria!E$2:E$1097,Serie_Diaria!$B$2:$B$1097,$A15) -> 236.57692 | E15: =AVERAGEIFS(Serie_Diaria!F$2:F$1097,Serie_Diaria!$B$2:$B$1097,$A15) -> 397.9359
A16: Sexta-feira | B16: =AVERAGEIFS(Serie_Diaria!C$2:C$1097,Serie_Diaria!$B$2:$B$1097,$A16) -> 20.121795 | C16: =AVERAGEIFS(Serie_Diaria!D$2:D$1097,Serie_Diaria!$B$2:$B$1097,$A16) -> 158.73077 | D16: =AVERAGEIFS(Serie_Diaria!E$2:E$1097,Serie_Diaria!$B$2:$B$1097,$A16) -> 281.23718 | E16: =AVERAGEIFS(Serie_Diaria!F$2:F$1097,Serie_Diaria!$B$2:$B$1097,$A16) -> 460.08974
A17: Sábado | B17: =AVERAGEIFS(Serie_Diaria!C$2:C$1097,Serie_Diaria!$B$2:$B$1097,$A17) -> 21.878205 | C17: =AVERAGEIFS(Serie_Diaria!D$2:D$1097,Serie_Diaria!$B$2:$B$1097,$A17) -> 142.00641 | D17: =AVERAGEIFS(Serie_Diaria!E$2:E$1097,Serie_Diaria!$B$2:$B$1097,$A17) -> 325.85256 | E17: =AVERAGEIFS(Serie_Diaria!F$2:F$1097,Serie_Diaria!$B$2:$B$1097,$A17) -> 489.73718
A18: Domingo | B18: =AVERAGEIFS(Serie_Diaria!C$2:C$1097,Serie_Diaria!$B$2:$B$1097,$A18) -> 20.687898 | C18: =AVERAGEIFS(Serie_Diaria!D$2:D$1097,Serie_Diaria!$B$2:$B$1097,$A18) -> 117.82166 | D18: =AVERAGEIFS(Serie_Diaria!E$2:E$1097,Serie_Diaria!$B$2:$B$1097,$A18) -> 315.21019 | E18: =AVERAGEIFS(Serie_Diaria!F$2:F$1097,Serie_Diaria!$B$2:$B$1097,$A18) -> 453.71975
A21: Dias com feriado/data especial versus dias comuns (apenas treino)
A22: Tipo de dia | B22: Vida | C22: Patrimônio | D22: Ordem pública | E22: Total
A23: Feriado / data especial | B23: =AVERAGEIFS(Serie_Diaria!C$2:C$1097,Serie_Diaria!$G$2:$G$1097,1) -> 19.646154 | C23: =AVERAGEIFS(Serie_Diaria!D$2:D$1097,Serie_Diaria!$G$2:$G$1097,1) -> 124.81538 | D23: =AVERAGEIFS(Serie_Diaria!E$2:E$1097,Serie_Diaria!$G$2:$G$1097,1) -> 302.73846 | E23: =AVERAGEIFS(Serie_Diaria!F$2:F$1097,Serie_Diaria!$G$2:$G$1097,1) -> 447.2
A24: Dia comum | B24: =AVERAGEIFS(Serie_Diaria!C$2:C$1097,Serie_Diaria!$G$2:$G$1097,0) -> 18.744908 | C24: =AVERAGEIFS(Serie_Diaria!D$2:D$1097,Serie_Diaria!$G$2:$G$1097,0) -> 142.09505 | D24: =AVERAGEIFS(Serie_Diaria!E$2:E$1097,Serie_Diaria!$G$2:$G$1097,0) -> 255.78371 | E24: =AVERAGEIFS(Serie_Diaria!F$2:F$1097,Serie_Diaria!$G$2:$G$1097,0) -> 416.62367
A25: Razão feriado/comum | B25: =B23/B24 -> 1.0480795 | C25: =C23/C24 -> 0.87839359 | D25: =D23/D24 -> 1.1835721 | E25: =E23/E24 -> 1.0733908
A28: Parâmetros de dimensionamento
A29: Produtividade (ligações atendidas por operador/hora) | B29: 12
A30: Horas efetivas por operador por turno | B30: 6
A31: Margem de segurança sobre a previsão | B31: 0.15
A32: Operadores-turno necessários (média, total diário + margem) | B32: =ROUNDUP(B7*(1+B31)/(B29*B30),0) -> 7
A33: Obs.: parâmetros hipotéticos, sem fonte oficial; fornecidos pelo autor da instância apenas para exemplificar a conversão previsão → capacidade.
