Workbook

Sheet Leia_Me
A1: PREVISÃO DE DEMANDA HOTELEIRA — LITORAL DO CEARÁ | MODELOS RNN
A2: Objetivo | B2: Instância para previsão diária de hóspedes hospedados em três hotéis do litoral do Ceará, apoiando planejamento de capacidade, equipes e serviços.
A3: Variável-alvo | B3: Hospedes_Hospedados: quantidade de hóspedes presentes no hotel por dia.
A4: Período | B4: 01/01/2023 a 31/12/2025 (1.096 dias por hotel; 3.288 observações hotel-dia).
A5: Hotéis | B5: Hotel Oceano Fortaleza (Fortaleza); Resort Dunas Portuárias (Aquiraz/Porto das Dunas); Pousada Jericoacoara Azul (Jijoca de Jericoacoara).
A6: Modelo | B6: RNN para séries temporais: SimpleRNN, LSTM ou GRU. Pode-se treinar um modelo por hotel ou um modelo global com identificação do hotel.
A7: Janela inicial sugerida | B7: 28 dias de histórico para prever o próximo dia; testar janelas de 7, 14, 28 e 56 dias.
A8: Atenção — uso | B8: Hospedes_Checkin, Hospedes_Checkout, Quartos_Ocupados, Taxa_Ocupacao e Diaria_Media_R$ são indicadores operacionais de apoio; não use valores observados do próprio dia como preditores se eles não forem conhecidos no instante da previsão.
A9: Atenção — reservas | B9: Reservas_Confirmadas_D14 representa hóspedes em reservas conhecidas 14 dias antes da data de hospedagem; é uma variável exógena simulada e disponível com antecedência.
A10: Atenção — clima | B10: Chuva_mm e Temperatura_Max_C são observações climáticas sintéticas. Para prever datas futuras, substitua-as por previsões meteorológicas disponíveis no momento da decisão ou exclua-as.
A11: Atenção — calendário | B11: Evento_Local_Simulado marca eventos ilustrativos, sem correspondência garantida com datas oficiais de eventos turísticos.
A12: Importação Python | B12: Use a aba Dados_Longos para treinar modelos individuais ou globais; ordene por Hotel_ID e Data e não embaralhe aleatoriamente as datas.
A13: Arquivos | B13: Serie_Diaria = formato amplo; Dados_Longos = formato recomendado para RNN; Calendario = variáveis de calendário; Cadastro_Hoteis = características de cada hotel; Dicionario = variáveis; Painel = estatísticas e gráfico.

Sheet Cadastro_Hoteis
A1: Hotel_ID | B1: Hotel | C1: Municipio | D1: Regiao_Litoranea | E1: Perfil | F1: Numero_Quartos | G1: Capacidade_Hospedes | H1: Hospedes_Medios_por_Quarto
A2: H01 | B2: Hotel Oceano Fortaleza | C2: Fortaleza | D2: Litoral de Fortaleza | E2: Urbano / lazer e negócios | F2: 140 | G2: 360 | H2: 2.35
A3: H02 | B3: Resort Dunas Portuária | C3: Aquiraz | D3: Porto das Dunas | E3: Resort / famílias e lazer | F3: 125 | G3: 320 | H3: 2.4
A4: H03 | B4: Pousada Jericoacoara Azul | C4: Jijoca de Jericoacoara | D4: Litoral Oeste | E4: Praia / lazer e natureza | F4: 85 | G4: 210 | H4: 2.25

Sheet Calendario
A1: Data | B1: Dia_Semana_Nome | C1: Dia_Semana | D1: Mes | E1: Dia_Ano | F1: Fim_De_Semana | G1: Feriado | H1: Nome_Feriado | I1: Ferias_Escolares | J1: Carnaval | K1: Reveillon | L1: Evento_Local_Simulado | M1: Chuva_mm | N1: Temperatura_Max_C
A2: 44927 | B2: Domingo | C2: 6 | D2: 1 | E2: 1 | F2: 1 | G2: 1 | H2: Confraternização Universal | I2: 1 | J2: 0 | K2: 1 | L2: 0 | M2: 1.2 | N2: 28
A3: 44928 | B3: Segunda | C3: 0 | D3: 1 | E3: 2 | F3: 0 | G3: 0 | I3: 1 | J3: 0 | K3: 1 | L3: 0 | M3: 1.4 | N3: 28
A4: 44929 | B4: Terça | C4: 1 | D4: 1 | E4: 3 | F4: 0 | G4: 0 | I4: 1 | J4: 0 | K4: 0 | L4: 0 | M4: 0 | N4: 29.9
A5: 44930 | B5: Quarta | C5: 2 | D5: 1 | E5: 4 | F5: 0 | G5: 0 | I5: 1 | J5: 0 | K5: 0 | L5: 0 | M5: 0 | N5: 29
A6: 44931 | B6: Quinta | C6: 3 | D6: 1 | E6: 5 | F6: 0 | G6: 0 | I6: 1 | J6: 0 | K6: 0 | L6: 0 | M6: 0 | N6: 29.3
A7: 44932 | B7: Sexta | C7: 4 | D7: 1 | E7: 6 | F7: 0 | G7: 0 | I7: 1 | J7: 0 | K7: 0 | L7: 0 | M7: 1.1 | N7: 28.2
A8: 44933 | B8: Sábado | C8: 5 | D8: 1 | E8: 7 | F8: 1 | G8: 0 | I8: 1 | J8: 0 | K8: 0 | L8: 0 | M8: 0 | N8: 28.6
A9: 44934 | B9: Domingo | C9: 6 | D9: 1 | E9: 8 | F9: 1 | G9: 0 | I9: 1 | J9: 0 | K9: 0 | L9: 0 | M9: 18.7 | N9: 27.4
A10: 44935 | B10: Segunda | C10: 0 | D10: 1 | E10: 9 | F10: 0 | G10: 0 | I10: 1 | J10: 0 | K10: 0 | L10: 0 | M10: 3.8 | N10: 28.4
A11: 44936 | B11: Terça | C11: 1 | D11: 1 | E11: 10 | F11: 0 | G11: 0 | I11: 1 | J11: 0 | K11: 0 | L11: 0 | M11: 1 | N11: 28.5
A12: 44937 | B12: Quarta | C12: 2 | D12: 1 | E12: 11 | F12: 0 | G12: 0 | I12: 1 | J12: 0 | K12: 0 | L12: 0 | M12: 0 | N12: 28.8
A13: 44938 | B13: Quinta | C13: 3 | D13: 1 | E13: 12 | F13: 0 | G13: 0 | I13: 1 | J13: 0 | K13: 0 | L13: 0 | M13: 0 | N13: 28.1
A14: 44939 | B14: Sexta | C14: 4 | D14: 1 | E14: 13 | F14: 0 | G14: 0 | I14: 1 | J14: 0 | K14: 0 | L14: 0 | M14: 0 | N14: 29.8
... A78: 45003 | B78: Sábado | C78: 5 | D78: 3 | E78: 77 | F78: 1 | G78: 0 | I78: 0 | J78: 0 | K78: 0 | L78: 0 | M78: 10.1 | N78: 27.7
A79: 45004 | B79: Domingo | C79: 6 | D79: 3 | E79: 78 | F79: 1 | G79: 1 | H79: Dia de São José (CE) | I79: 0 | J79: 0 | K79: 0 | L79: 0 | M79: 10.6 | N79: 25.4
A80: 45005 | B80: Segunda | C80: 0 | D80: 3 | E80: 79 | F80: 0 | G80: 0 | I80: 0 | J80: 0 | K80: 0 | L80: 0 | M80: 32.4 | N80: 28.4
A81: 45006 | B81: Terça | C81: 1 | D81: 3 | E81: 80 | F81: 0 | G81: 0 | I81: 0 | J81: 0 | K81: 0 | L81: 0 | M81: 4.8 | N81: 28.1
A82: 45007 | B82: Quarta | C82: 2 | D82: 3 | E82: 81 | F82: 0 | G82: 0 | I82: 0 | J82: 0 | K82: 0 | L82: 0 | M82: 21 | N82: 28.6
A83: 45008 | B83: Quinta | C83: 3 | D83: 3 | E83: 82 | F83: 0 | G83: 0 | I83: 0 | J83: 0 | K83: 0 | L83: 0 | M83: 14.3 | N83: 26.1
A84: 45009 | B84: Sexta | C84: 4 | D84: 3 | E84: 83 | F84: 0 | G84: 0 | I84: 0 | J84: 0 | K84: 0 | L84: 0 | M84: 15.6 | N84: 28
A85: 45010 | B85: Sábado | C85: 5 | D85: 3 | E85: 84 | F85: 1 | G85: 1 | H85: Data Magna do Ceará | I85: 0 | J85: 0 | K85: 0 | L85: 0 | M85: 2.1 | N85: 27.3
A86: 45011 | B86: Domingo | C86: 6 | D86: 3 | E86: 85 | F86: 1 | G86: 0 | I86: 0 | J86: 0 | K86: 0 | L86: 0 | M86: 6.9 | N86: 27.9
A87: 45012 | B87: Segunda | C87: 0 | D87: 3 | E87: 86 | F87: 0 | G87: 0 | I87: 0 | J87: 0 | K87: 0 | L87: 0 | M87: 12.1 | N87: 26.6
A88: 45013 | B88: Terça | C88: 1 | D88: 3 | E88: 87 | F88: 0 | G88: 0 | I88: 0 | J88: 0 | K88: 0 | L88: 0 | M88: 5.4 | N88: 26.5
A89: 45014 | B89: Quarta | C89: 2 | D89: 3 | E89: 88 | F89: 0 | G89: 0 | I89: 0 | J89: 0 | K89: 0 | L89: 0 | M89: 10.6 | N89: 28.8
A90: 45015 | B90: Quinta | C90: 3 | D90: 3 | E90: 89 | F90: 0 | G90: 0 | I90: 0 | J90: 0 | K90: 0 | L90: 0 | M90: 12.2 | N90: 27.8
A91: 45016 | B91: Sexta | C91: 4 | D91: 3 | E91: 90 | F91: 0 | G91: 0 | I91: 0 | J91: 0 | K91: 0 | L91: 0 | M91: 18.9 | N91: 27.5
A92: 45017 | B92: Sábado | C92: 5 | D92: 4 | E92: 91 | F92: 1 | G92: 0 | I92: 0 | J92: 0 | K92: 0 | L92: 0 | M92: 7.5 | N92: 26.6
A93: 45018 | B93: Domingo | C93: 6 | D93: 4 | E93: 92 | F93: 1 | G93: 0 | I93: 0 | J93: 0 | K93: 0 | L93: 0 | M93: 6.9 | N93: 27
A94: 45019 | B94: Segunda | C94: 0 | D94: 4 | E94: 93 | F94: 0 | G94: 0 | I94: 0 | J94: 0 | K94: 0 | L94: 0 | M94: 12.1 | N94: 27.3
A95: 45020 | B95: Terça | C95: 1 | D95: 4 | E95: 94 | F95: 0 | G95: 0 | I95: 0 | J95: 0 | K95: 0 | L95: 0 | M95: 2.4 | N95: 27
A96: 45021 | B96: Quarta | C96: 2 | D96: 4 | E96: 95 | F96: 0 | G96: 0 | I96: 0 | J96: 0 | K96: 0 | L96: 0 | M96: 0 | N96: 27.3
A97: 45022 | B97: Quinta | C97: 3 | D97: 4 | E97: 96 | F97: 0 | G97: 0 | I97: 0 | J97: 0 | K97: 0 | L97: 0 | M97: 8.1 | N97: 27
... A111: 45036 | B111: Quinta | C111: 3 | D111: 4 | E111: 110 | F111: 0 | G111: 0 | I111: 0 | J111: 0 | K111: 0 | L111: 0 | M111: 23.5 | N111: 26.6
A112: 45037 | B112: Sexta | C112: 4 | D112: 4 | E112: 111 | F112: 0 | G112: 1 | H112: Tiradentes | I112: 0 | J112: 0 | K112: 0 | L112: 0 | M112: 5 | N112: 28
A113: 45038 | B113: Sábado | C113: 5 | D113: 4 | E113: 112 | F113: 1 | G113: 0 | I113: 0 | J113: 0 | K113: 0 | L113: 0 | M113: 10.5 | N113: 27.3
A114: 45039 | B114: Domingo | C114: 6 | D114: 4 | E114: 113 | F114: 1 | G114: 0 | I114: 0 | J114: 0 | K114: 0 | L114: 0 | M114: 6 | N114: 28.2
A115: 45040 | B115: Segunda | C115: 0 | D115: 4 | E115: 114 | F115: 0 | G115: 0 | I115: 0 | J115: 0 | K115: 0 | L115: 0 | M115: 15.3 | N115: 25.4
A116: 45041 | B116: Terça | C116: 1 | D116: 4 | E116: 115 | F116: 0 | G116: 0 | I116: 0 | J116: 0 | K116: 0 | L116: 0 | M116: 14.8 | N116: 25.7
...

Sheet Serie_Diaria
A1: Data | B1: Dia_Semana_Nome | C1: Dia_Semana | D1: Mes | E1: Fim_De_Semana | F1: Feriado | G1: Nome_Feriado | H1: Ferias_Escolares | I1: Carnaval | J1: Reveillon | K1: Evento_Local_Simulado | L1: Chuva_mm | M1: Temperatura_Max_C | N1: Hospedes_H01 | O1: Reservas_D14_H01 | P1: Taxa_Ocupacao_H01 | Q1: Hospedes_H02 | R1: Reservas_D14_H02 | S1: Taxa_Ocupacao_H02 | T1: Hospedes_H03 | U1: Reservas_D14_H03 | V1: Taxa_Ocupacao_H03 | W1: Total_Hospedes
A2: 44927 | B2: Domingo | C2: 6 | D2: 1 | E2: 1 | F2: 1 | G2: Confraternização Universal | H2: 1 | I2: 0 | J2: 1 | K2: 0 | L2: 1.2 | M2: 28 | N2: 284 | O2: 255 | P2: 0.86428571 | Q2: 284 | R2: 259 | S2: 0.968 | T2: 188 | U2: 158 | V2: 0.96470588 | W2: =N2+Q2+T2 -> 756
A3: 44928 | B3: Segunda | C3: 0 | D3: 1 | E3: 0 | F3: 0 | H3: 1 | I3: 0 | J3: 1 | K3: 0 | L3: 1.4 | M3: 28 | N3: 260 | O3: 244 | P3: 0.8 | Q3: 269 | R3: 237 | S3: 0.896 | T3: 186 | U3: 168 | V3: 0.96470588 | W3: =N3+Q3+T3 -> 715
A4: 44929 | B4: Terça | C4: 1 | D4: 1 | E4: 0 | F4: 0 | H4: 1 | I4: 0 | J4: 0 | K4: 0 | L4: 0 | M4: 29.9 | N4: 219 | O4: 193 | P4: 0.66428571 | Q4: 211 | R4: 195 | S4: 0.704 | T4: 140 | U4: 121 | V4: 0.74117647 | W4: =N4+Q4+T4 -> 570
A5: 44930 | B5: Quarta | C5: 2 | D5: 1 | E5: 0 | F5: 0 | H5: 1 | I5: 0 | J5: 0 | K5: 0 | L5: 0 | M5: 29 | N5: 205 | O5: 187 | P5: 0.64285714 | Q5: 243 | R5: 197 | S5: 0.792 | T5: 152 | U5: 130 | V5: 0.78823529 | W5: =N5+Q5+T5 -> 600
A6: 44931 | B6: Quinta | C6: 3 | D6: 1 | E6: 0 | F6: 0 | H6: 1 | I6: 0 | J6: 0 | K6: 0 | L6: 0 | M6: 29.3 | N6: 221 | O6: 206 | P6: 0.65 | Q6: 226 | R6: 201 | S6: 0.768 | T6: 150 | U6: 134 | V6: 0.8 | W6: =N6+Q6+T6 -> 597
A7: 44932 | B7: Sexta | C7: 4 | D7: 1 | E7: 0 | F7: 0 | H7: 1 | I7: 0 | J7: 0 | K7: 0 | L7: 1.1 | M7: 28.2 | N7: 230 | O7: 206 | P7: 0.7 | Q7: 211 | R7: 178 | S7: 0.712 | T7: 151 | U7: 136 | V7: 0.75294118 | W7: =N7+Q7+T7 -> 592
A8: 44933 | B8: Sábado | C8: 5 | D8: 1 | E8: 1 | F8: 0 | H8: 1 | I8: 0 | J8: 0 | K8: 0 | L8: 0 | M8: 28.6 | N8: 248 | O8: 231 | P8: 0.74285714 | Q8: 253 | R8: 227 | S8: 0.848 | T8: 182 | U8: 155 | V8: 0.95294118 | W8: =N8+Q8+T8 -> 683
A9: 44934 | B9: Domingo | C9: 6 | D9: 1 | E9: 1 | F9: 0 | H9: 1 | I9: 0 | J9: 0 | K9: 0 | L9: 18.7 | M9: 27.4 | N9: 246 | O9: 220 | P9: 0.74285714 | Q9: 259 | R9: 239 | S9: 0.872 | T9: 181 | U9: 165 | V9: 0.92941176 | W9: =N9+Q9+T9 -> 686
A10: 44935 | B10: Segunda | C10: 0 | D10: 1 | E10: 0 | F10: 0 | H10: 1 | I10: 0 | J10: 0 | K10: 0 | L10: 3.8 | M10: 28.4 | N10: 211 | O10: 178 | P10: 0.62857143 | Q10: 217 | R10: 192 | S10: 0.744 | T10: 155 | U10: 130 | V10: 0.82352941 | W10: =N10+Q10+T10 -> 583
A11: 44936 | B11: Terça | C11: 1 | D11: 1 | E11: 0 | F11: 0 | H11: 1 | I11: 0 | J11: 0 | K11: 0 | L11: 1 | M11: 28.5 | N11: 213 | O11: 174 | P11: 0.65714286 | Q11: 228 | R11: 204 | S11: 0.768 | T11: 169 | U11: 152 | V11: 0.87058824 | W11: =N11+Q11+T11 -> 610
A12: 44937 | B12: Quarta | C12: 2 | D12: 1 | E12: 0 | F12: 0 | H12: 1 | I12: 0 | J12: 0 | K12: 0 | L12: 0 | M12: 28.8 | N12: 201 | O12: 176 | P12: 0.60714286 | Q12: 221 | R12: 206 | S12: 0.72 | T12: 156 | U12: 143 | V12: 0.83529412 | W12: =N12+Q12+T12 -> 578
A13: 44938 | B13: Quinta | C13: 3 | D13: 1 | E13: 0 | F13: 0 | H13: 1 | I13: 0 | J13: 0 | K13: 0 | L13: 0 | M13: 28.1 | N13: 244 | O13: 207 | P13: 0.74285714 | Q13: 233 | R13: 216 | S13: 0.784 | T13: 157 | U13: 131 | V13: 0.82352941 | W13: =N13+Q13+T13 -> 634
A14: 44939 | B14: Sexta | C14: 4 | D14: 1 | E14: 0 | F14: 0 | H14: 1 | I14: 0 | J14: 0 | K14: 0 | L14: 0 | M14: 29.8 | N14: 242 | O14: 198 | P14: 0.73571429 | Q14: 218 | R14: 196 | S14: 0.736 | T14: 160 | U14: 147 | V14: 0.83529412 | W14: =N14+Q14+T14 -> 620
... A78: 45003 | B78: Sábado | C78: 5 | D78: 3 | E78: 1 | F78: 0 | H78: 0 | I78: 0 | J78: 0 | K78: 0 | L78: 10.1 | M78: 27.7 | N78: 201 | O78: 176 | P78: 0.6 | Q78: 188 | R78: 174 | S78: 0.64 | T78: 133 | U78: 113 | V78: 0.69411765 | W78: =N78+Q78+T78 -> 522
A79: 45004 | B79: Domingo | C79: 6 | D79: 3 | E79: 1 | F79: 1 | G79: Dia de São José (CE) | H79: 0 | I79: 0 | J79: 0 | K79: 0 | L79: 10.6 | M79: 25.4 | N79: 210 | O79: 173 | P79: 0.63571429 | Q79: 199 | R79: 167 | S79: 0.672 | T79: 147 | U79: 135 | V79: 0.77647059 | W79: =N79+Q79+T79 -> 556
A80: 45005 | B80: Segunda | C80: 0 | D80: 3 | E80: 0 | F80: 0 | H80: 0 | I80: 0 | J80: 0 | K80: 0 | L80: 32.4 | M80: 28.4 | N80: 182 | O80: 153 | P80: 0.55714286 | Q80: 143 | R80: 118 | S80: 0.464 | T80: 113 | U80: 105 | V80: 0.56470588 | W80: =N80+Q80+T80 -> 438
A81: 45006 | B81: Terça | C81: 1 | D81: 3 | E81: 0 | F81: 0 | H81: 0 | I81: 0 | J81: 0 | K81: 0 | L81: 4.8 | M81: 28.1 | N81: 176 | O81: 152 | P81: 0.53571429 | Q81: 140 | R81: 114 | S81: 0.448 | T81: 108 | U81: 92 | V81: 0.57647059 | W81: =N81+Q81+T81 -> 424
A82: 45007 | B82: Quarta | C82: 2 | D82: 3 | E82: 0 | F82: 0 | H82: 0 | I82: 0 | J82: 0 | K82: 0 | L82: 21 | M82: 28.6 | N82: 176 | O82: 147 | P82: 0.52857143 | Q82: 148 | R82: 137 | S82: 0.504 | T82: 111 | U82: 97 | V82: 0.56470588 | W82: =N82+Q82+T82 -> 435
A83: 45008 | B83: Quinta | C83: 3 | D83: 3 | E83: 0 | F83: 0 | H83: 0 | I83: 0 | J83: 0 | K83: 0 | L83: 14.3 | M83: 26.1 | N83: 160 | O83: 142 | P83: 0.5 | Q83: 125 | R83: 101 | S83: 0.44 | T83: 100 | U83: 85 | V83: 0.51764706 | W83: =N83+Q83+T83 -> 385
A84: 45009 | B84: Sexta | C84: 4 | D84: 3 | E84: 0 | F84: 0 | H84: 0 | I84: 0 | J84: 0 | K84: 0 | L84: 15.6 | M84: 28 | N84: 190 | O84: 175 | P84: 0.57857143 | Q84: 158 | R84: 137 | S84: 0.52 | T84: 109 | U84: 99 | V84: 0.6 | W84: =N84+Q84+T84 -> 457
A85: 45010 | B85: Sábado | C85: 5 | D85: 3 | E85: 1 | F85: 1 | G85: Data Magna do Ceará | H85: 0 | I85: 0 | J85: 0 | K85: 0 | L85: 2.1 | M85: 27.3 | N85: 226 | O85: 209 | P85: 0.68571429 | Q85: 196 | R85: 179 | S85: 0.656 | T85: 148 | U85: 135 | V85: 0.81176471 | W85: =N85+Q85+T85 -> 570
A86: 45011 | B86: Domingo | C86: 6 | D86: 3 | E86: 1 | F86: 0 | H86: 0 | I86: 0 | J86: 0 | K86: 0 | L86: 6.9 | M86: 27.9 | N86: 203 | O86: 167 | P86: 0.62142857 | Q86: 180 | R86: 147 | S86: 0.584 | T86: 138 | U86: 120 | V86: 0.71764706 | W86: =N86+Q86+T86 -> 521
A87: 45012 | B87: Segunda | C87: 0 | D87: 3 | E87: 0 | F87: 0 | H87: 0 | I87: 0 | J87: 0 | K87: 0 | L87: 12.1 | M87: 26.6 | N87: 192 | O87: 177 | P87: 0.58571429 | Q87: 171 | R87: 151 | S87: 0.56 | T87: 103 | U87: 92 | V87: 0.55294118 | W87: =N87+Q87+T87 -> 466
A88: 45013 | B88: Terça | C88: 1 | D88: 3 | E88: 0 | F88: 0 | H88: 0 | I88: 0 | J88: 0 | K88: 0 | L88: 5.4 | M88: 26.5 | N88: 176 | O88: 165 | P88: 0.52142857 | Q88: 171 | R88: 152 | S88: 0.56 | T88: 114 | U88: 105 | V88: 0.61176471 | W88: =N88+Q88+T88 -> 461
A89: 45014 | B89: Quarta | C89: 2 | D89: 3 | E89: 0 | F89: 0 | H89: 0 | I89: 0 | J89: 0 | K89: 0 | L89: 10.6 | M89: 28.8 | N89: 172 | O89: 138 | P89: 0.52857143 | Q89: 144 | R89: 116 | S89: 0.488 | T89: 122 | U89: 106 | V89: 0.58823529 | W89: =N89+Q89+T89 -> 438
A90: 45015 | B90: Quinta | C90: 3 | D90: 3 | E90: 0 | F90: 0 | H90: 0 | I90: 0 | J90: 0 | K90: 0 | L90: 12.2 | M90: 27.8 | N90: 151 | O90: 132 | P90: 0.48571429 | Q90: 169 | R90: 140 | S90: 0.56 | T90: 125 | U90: 116 | V90: 0.63529412 | W90: =N90+Q90+T90 -> 445
A91: 45016 | B91: Sexta | C91: 4 | D91: 3 | E91: 0 | F91: 0 | H91: 0 | I91: 0 | J91: 0 | K91: 0 | L91: 18.9 | M91: 27.5 | N91: 157 | O91: 141 | P91: 0.5 | Q91: 132 | R91: 109 | S91: 0.456 | T91: 114 | U91: 95 | V91: 0.6 | W91: =N91+Q91+T91 -> 403
A92: 45017 | B92: Sábado | C92: 5 | D92: 4 | E92: 1 | F92: 0 | H92: 0 | I92: 0 | J92: 0 | K92: 0 | L92: 7.5 | M92: 26.6 | N92: 207 | O92: 179 | P92: 0.63571429 | Q92: 180 | R92: 155 | S92: 0.608 | T92: 123 | U92: 111 | V92: 0.63529412 | W92: =N92+Q92+T92 -> 510
A93: 45018 | B93: Domingo | C93: 6 | D93: 4 | E93: 1 | F93: 0 | H93: 0 | I93: 0 | J93: 0 | K93: 0 | L93: 6.9 | M93: 27 | N93: 211 | O93: 194 | P93: 0.65714286 | Q93: 185 | R93: 163 | S93: 0.624 | T93: 143 | U93: 131 | V93: 0.74117647 | W93: =N93+Q93+T93 -> 539
A94: 45019 | B94: Segunda | C94: 0 | D94: 4 | E94: 0 | F94: 0 | H94: 0 | I94: 0 | J94: 0 | K94: 0 | L94: 12.1 | M94: 27.3 | N94: 185 | O94: 155 | P94: 0.54285714 | Q94: 148 | R94: 127 | S94: 0.496 | T94: 99 | U94: 80 | V94: 0.50588235 | W94: =N94+Q94+T94 -> 432
A95: 45020 | B95: Terça | C95: 1 | D95: 4 | E95: 0 | F95: 0 | H95: 0 | I95: 0 | J95: 0 | K95: 0 | L95: 2.4 | M95: 27 | N95: 158 | O95: 129 | P95: 0.50714286 | Q95: 141 | R95: 132 | S95: 0.48 | T95: 123 | U95: 115 | V95: 0.61176471 | W95: =N95+Q95+T95 -> 422
A96: 45021 | B96: Quarta | C96: 2 | D96: 4 | E96: 0 | F96: 0 | H96: 0 | I96: 0 | J96: 0 | K96: 0 | L96: 0 | M96: 27.3 | N96: 175 | O96: 156 | P96: 0.51428571 | Q96: 152 | R96: 141 | S96: 0.52 | T96: 94 | U96: 76 | V96: 0.52941176 | W96: =N96+Q96+T96 -> 421
A97: 45022 | B97: Quinta | C97: 3 | D97: 4 | E97: 0 | F97: 0 | H97: 0 | I97: 0 | J97: 0 | K97: 0 | L97: 8.1 | M97: 27 | N97: 191 | O97: 164 | P97: 0.57857143 | Q97: 156 | R97: 131 | S97: 0.504 | T97: 102 | U97: 94 | V97: 0.50588235 | W97: =N97+Q97+T97 -> 449
... A111: 45036 | B111: Quinta | C111: 3 | D111: 4 | E111: 0 | F111: 0 | H111: 0 | I111: 0 | J111: 0 | K111: 0 | L111: 23.5 | M111: 26.6 | N111: 171 | O111: 152 | P111: 0.5 | Q111: 168 | R111: 150 | S111: 0.552 | T111: 102 | U111: 93 | V111: 0.52941176 | W111: =N111+Q111+T111 -> 441
A112: 45037 | B112: Sexta | C112: 4 | D112: 4 | E112: 0 | F112: 1 | G112: Tiradentes | H112: 0 | I112: 0 | J112: 0 | K112: 0 | L112: 5 | M112: 28 | N112: 206 | O112: 183 | P112: 0.60714286 | Q112: 186 | R112: 174 | S112: 0.608 | T112: 119 | U112: 96 | V112: 0.63529412 | W112: =N112+Q112+T112 -> 511
A113: 45038 | B113: Sábado | C113: 5 | D113: 4 | E113: 1 | F113: 0 | H113: 0 | I113: 0 | J113: 0 | K113: 0 | L113: 10.5 | M113: 27.3 | N113: 194 | O113: 160 | P113: 0.59285714 | Q113: 182 | R113: 154 | S113: 0.624 | T113: 127 | U113: 111 | V113: 0.67058824 | W113: =N113+Q113+T113 -> 503
A114: 45039 | B114: Domingo | C114: 6 | D114: 4 | E114: 1 | F114: 0 | H114: 0 | I114: 0 | J114: 0 | K114: 0 | L114: 6 | M114: 28.2 | N114: 205 | O114: 192 | P114: 0.60714286 | Q114: 176 | R114: 165 | S114: 0.592 | T114: 128 | U114: 112 | V114: 0.64705882 | W114: =N114+Q114+T114 -> 509
A115: 45040 | B115: Segunda | C115: 0 | D115: 4 | E115: 0 | F115: 0 | H115: 0 | I115: 0 | J115: 0 | K115: 0 | L115: 15.3 | M115: 25.4 | N115: 158 | O115: 135 | P115: 0.47857143 | Q115: 154 | R115: 134 | S115: 0.504 | T115: 115 | U115: 97 | V115: 0.54117647 | W115: =N115+Q115+T115 -> 427
A116: 45041 | B116: Terça | C116: 1 | D116: 4 | E116: 0 | F116: 0 | H116: 0 | I116: 0 | J116: 0 | K116: 0 | L116: 14.8 | M116: 25.7 | N116: 171 | O116: 155 | P116: 0.52857143 | Q116: 145 | R116: 135 | S116: 0.48 | T116: 121 | U116: 107 | V116: 0.63529412 | W116: =N116+Q116+T116 -> 437
...

Sheet Dados_Longos
A1: Data | B1: Hotel_ID | C1: Hotel | D1: Municipio | E1: Regiao_Litoranea | F1: Numero_Quartos | G1: Capacidade_Hospedes | H1: Hospedes_Hospedados | I1: Quartos_Ocupados | J1: Taxa_Ocupacao | K1: Hospedes_Checkin | L1: Hospedes_Checkout | M1: Reservas_Confirmadas_D14 | N1: Diaria_Media_R$ | O1: Chuva_mm | P1: Temperatura_Max_C | Q1: Dia_Semana | R1: Dia_Semana_Nome | S1: Mes | T1: Dia_Ano | U1: Dia_Semana_Sin | V1: Dia_Semana_Cos | W1: Dia_Ano_Sin | X1: Dia_Ano_Cos | Y1: Fim_De_Semana | Z1: Feriado | AA1: Nome_Feriado | AB1: Ferias_Escolares | AC1: Carnaval | AD1: Reveillon | AE1: Evento_Local_Simulado
A2: 44927 | B2: H01 | C2: Hotel Atlântico Fortaleza | D2: Fortaleza | E2: Litoral de Fortaleza | F2: 140 | G2: 360 | H2: 284 | I2: 121 | J2: 0.86428571 | K2: 72 | L2: 57 | M2: 255 | N2: 487.62 | O2: 1.2 | P2: 28 | Q2: 6 | R2: Domingo | S2: 1 | T2: 1 | U2: -0.78183148 | V2: 0.6234898 | W2: 0 | X2: 1 | Y2: 1 | Z2: 1 | AA2: Confraternização Universal | AB2: 1 | AC2: 0 | AD2: 1 | AE2: 0
A3: 44927 | B3: H02 | C3: Resort Dunas do Porto | D3: Aquiraz | E3: Porto das Dunas | F3: 125 | G3: 320 | H3: 284 | I3: 121 | J3: 0.968 | K3: 39 | L3: 72 | M3: 259 | N3: 725.63 | O3: 1.2 | P3: 28 | Q3: 6 | R3: Domingo | S3: 1 | T3: 1 | U3: -0.78183148 | V3: 0.6234898 | W3: 0 | X3: 1 | Y3: 1 | Z3: 1 | AA3: Confraternização Universal | AB3: 1 | AC3: 0 | AD3: 1 | AE3: 0
A4: 44927 | B4: H03 | C4: Pousada Jericoacoara Azul | D4: Jijoca de Jericoacoara | E4: Litoral Oeste | F4: 85 | G4: 210 | H4: 188 | I4: 82 | J4: 0.96470588 | K4: 27 | L4: 49 | M4: 158 | N4: 602.95 | O4: 1.2 | P4: 28 | Q4: 6 | R4: Domingo | S4: 1 | T4: 1 | U4: -0.78183148 | V4: 0.6234898 | W4: 0 | X4: 1 | Y4: 1 | Z4: 1 | AA4: Confraternização Universal | AB4: 1 | AC4: 0 | AD4: 1 | AE4: 0
A5: 44928 | B5: H01 | C5: Hotel Atlântico Fortaleza | D5: Fortaleza | E5: Litoral de Fortaleza | F5: 140 | G5: 360 | H5: 260 | I5: 112 | J5: 0.8 | K5: 50 | L5: 53 | M5: 244 | N5: 443.38 | O5: 1.4 | P5: 28 | Q5: 0 | R5: Segunda | S5: 1 | T5: 2 | U5: 0 | V5: 1 | W5: 0.017201575 | X5: 0.99985204 | Y5: 0 | Z5: 0 | AB5: 1 | AC5: 0 | AD5: 1 | AE5: 0
A6: 44928 | B6: H02 | C6: Resort Dunas do Porto | D6: Aquiraz | E6: Porto das Dunas | F6: 125 | G6: 320 | H6: 269 | I6: 112 | J6: 0.896 | K6: 47 | L6: 60 | M6: 237 | N6: 607.63 | O6: 1.4 | P6: 28 | Q6: 0 | R6: Segunda | S6: 1 | T6: 2 | U6: 0 | V6: 1 | W6: 0.017201575 | X6: 0.99985204 | Y6: 0 | Z6: 0 | AB6: 1 | AC6: 0 | AD6: 1 | AE6: 0
A7: 44928 | B7: H03 | C7: Pousada Jericoacoara Azul | D7: Jijoca de Jericoacoara | E7: Litoral Oeste | F7: 85 | G7: 210 | H7: 186 | I7: 82 | J7: 0.96470588 | K7: 41 | L7: 35 | M7: 168 | N7: 572.84 | O7: 1.4 | P7: 28 | Q7: 0 | R7: Segunda | S7: 1 | T7: 2 | U7: 0 | V7: 1 | W7: 0.017201575 | X7: 0.99985204 | Y7: 0 | Z7: 0 | AB7: 1 | AC7: 0 | AD7: 1 | AE7: 0
A8: 44929 | B8: H01 | C8: Hotel Atlântico Fortaleza | D8: Fortaleza | E8: Litoral de Fortaleza | F8: 140 | G8: 360 | H8: 219 | I8: 93 | J8: 0.66428571 | K8: 41 | L8: 28 | M8: 193 | N8: 502.23 | O8: 0 | P8: 29.9 | Q8: 1 | R8: Terça | S8: 1 | T8: 3 | U8: 0.78183148 | V8: 0.6234898 | W8: 0.034398061 | X8: 0.99940821 | Y8: 0 | Z8: 0 | AB8: 1 | AC8: 0 | AD8: 0 | AE8: 0
A9: 44929 | B9: H02 | C9: Resort Dunas do Porto | D9: Aquiraz | E9: Porto das Dunas | F9: 125 | G9: 320 | H9: 211 | I9: 88 | J9: 0.704 | K9: 32 | L9: 59 | M9: 195 | N9: 633.46 | O9: 0 | P9: 29.9 | Q9: 1 | R9: Terça | S9: 1 | T9: 3 | U9: 0.78183148 | V9: 0.6234898 | W9: 0.034398061 | X9: 0.99940821 | Y9: 0 | Z9: 0 | AB9: 1 | AC9: 0 | AD9: 0 | AE9: 0
A10: 44929 | B10: H03 | C10: Pousada Jericoacoara Azul | D10: Jijoca de Jericoacoara | E10: Litoral Oeste | F10: 85 | G10: 210 | H10: 140 | I10: 63 | J10: 0.74117647 | K10: 35 | L10: 34 | M10: 121 | N10: 595.28 | O10: 0 | P10: 29.9 | Q10: 1 | R10: Terça | S10: 1 | T10: 3 | U10: 0.78183148 | V10: 0.6234898 | W10: 0.034398061 | X10: 0.99940821 | Y10: 0 | Z10: 0 | AB10: 1 | AC10: 0 | AD10: 0 | AE10: 0
A11: 44930 | B11: H01 | C11: Hotel Atlântico Fortaleza | D11: Fortaleza | E11: Litoral de Fortaleza | F11: 140 | G11: 360 | H11: 205 | I11: 90 | J11: 0.64285714 | K11: 47 | L11: 45 | M11: 187 | N11: 474.96 | O11: 0 | P11: 29 | Q11: 2 | R11: Quarta | S11: 1 | T11: 4 | U11: 0.97492791 | V11: -0.22252093 | W11: 0.051584367 | X11: 0.99866864 | Y11: 0 | Z11: 0 | AB11: 1 | AC11: 0 | AD11: 0 | AE11: 0
A12: 44930 | B12: H02 | C12: Resort Dunas do Porto | D12: Aquiraz | E12: Porto das Dunas | F12: 125 | G12: 320 | H12: 243 | I12: 99 | J12: 0.792 | K12: 35 | L12: 36 | M12: 197 | N12: 729.99 | O12: 0 | P12: 29 | Q12: 2 | R12: Quarta | S12: 1 | T12: 4 | U12: 0.97492791 | V12: -0.22252093 | W12: 0.051584367 | X12: 0.99866864 | Y12: 0 | Z12: 0 | AB12: 1 | AC12: 0 | AD12: 0 | AE12: 0
A13: 44930 | B13: H03 | C13: Pousada Jericoacoara Azul | D13: Jijoca de Jericoacoara | E13: Litoral Oeste | F13: 85 | G13: 210 | H13: 152 | I13: 67 | J13: 0.78823529 | K13: 19 | L13: 28 | M13: 130 | N13: 548.59 | O13: 0 | P13: 29 | Q13: 2 | R13: Quarta | S13: 1 | T13: 4 | U13: 0.97492791 | V13: -0.22252093 | W13: 0.051584367 | X13: 0.99866864 | Y13: 0 | Z13: 0 | AB13: 1 | AC13: 0 | AD13: 0 | AE13: 0
A14: 44931 | B14: H01 | C14: Hotel Atlântico Fortaleza | D14: Fortaleza | E14: Litoral de Fortaleza | F14: 140 | G14: 360 | H14: 221 | I14: 91 | J14: 0.65 | K14: 42 | L14: 38 | M14: 206 | N14: 471.22 | O14: 0 | P14: 29.3 | Q14: 3 | R14: Quinta | S14: 1 | T14: 5 | U14: 0.43388374 | V14: -0.90096887 | W14: 0.068755408 | X14: 0.99763355 | Y14: 0 | Z14: 0 | AB14: 1 | AC14: 0 | AD14: 0 | AE14: 0
A15: 44931 | B15: H02 | C15: Resort Dunas do Porto | D15: Aquiraz | E15: Porto das Dunas | F15: 125 | G15: 320 | H15: 226 | I15: 96 | J15: 0.768 | K15: 31 | L15: 29 | M15: 201 | N15: 624.97 | O15: 0 | P15: 29.3 | Q15: 3 | R15: Quinta | S15: 1 | T15: 5 | U15: 0.43388374 | V15: -0.90096887 | W15: 0.068755408 | X15: 0.99763355 | Y15: 0 | Z15: 0 | AB15: 1 | AC15: 0 | AD15: 0 | AE15: 0
A16: 44931 | B16: H03 | C16: Pousada Jericoacoara Azul | D16: Jijoca de Jericoacoara | E16: Litoral Oeste | F16: 85 | G16: 210 | H16: 150 | I16: 68 | J16: 0.8 | K16: 29 | L16: 33 | M16: 134 | N16: 550.32 | O16: 0 | P16: 29.3 | Q16: 3 | R16: Quinta | S16: 1 | T16: 5 | U16: 0.43388374 | V16: -0.90096887 | W16: 0.068755408 | X16: 0.99763355 | Y16: 0 | Z16: 0 | AB16: 1 | AC16: 0 | AD16: 0 | AE16: 0
... A232: 45003 | B232: H03 | C232: Pousada Jericoacoara Azul | D232: Jijoca de Jericoacoara | E232: Litoral Oeste | F232: 85 | G232: 210 | H232: 133 | I232: 59 | J232: 0.69411765 | K232: 26 | L232: 21 | M232: 113 | N232: 553.96 | O232: 10.1 | P232: 27.7 | Q232: 5 | R232: Sábado | S232: 3 | T232: 77 | U232: -0.97492791 | V232: -0.22252093 | W232: 0.96550717 | X232: 0.26037648 | Y232: 1 | Z232: 0 | AB232: 0 | AC232: 0 | AD232: 0 | AE232: 0
A233: 45004 | B233: H01 | C233: Hotel Atlântico Fortaleza | D233: Fortaleza | E233: Litoral de Fortaleza | F233: 140 | G233: 360 | H233: 210 | I233: 89 | J233: 0.63571429 | K233: 44 | L233: 22 | M233: 173 | N233: 515.55 | O233: 10.6 | P233: 25.4 | Q233: 6 | R233: Domingo | S233: 3 | T233: 78 | U233: -0.78183148 | V233: 0.6234898 | W233: 0.9698432 | X233: 0.24372971 | Y233: 1 | Z233: 1 | AA233: Dia de São José (CE) | AB233: 0 | AC233: 0 | AD233: 0 | AE233: 0
A234: 45004 | B234: H02 | C234: Resort Dunas do Porto | D234: Aquiraz | E234: Porto das Dunas | F234: 125 | G234: 320 | H234: 199 | I234: 84 | J234: 0.672 | K234: 22 | L234: 49 | M234: 167 | N234: 704.92 | O234: 10.6 | P234: 25.4 | Q234: 6 | R234: Domingo | S234: 3 | T234: 78 | U234: -0.78183148 | V234: 0.6234898 | W234: 0.9698432 | X234: 0.24372971 | Y234: 1 | Z234: 1 | AA234: Dia de São José (CE) | AB234: 0 | AC234: 0 | AD234: 0 | AE234: 0
A235: 45004 | B235: H03 | C235: Pousada Jericoacoara Azul | D235: Jijoca de Jericoacoara | E235: Litoral Oeste | F235: 85 | G235: 210 | H235: 147 | I235: 66 | J235: 0.77647059 | K235: 31 | L235: 29 | M235: 135 | N235: 556.89 | O235: 10.6 | P235: 25.4 | Q235: 6 | R235: Domingo | S235: 3 | T235: 78 | U235: -0.78183148 | V235: 0.6234898 | W235: 0.9698432 | X235: 0.24372971 | Y235: 1 | Z235: 1 | AA235: Dia de São José (CE) | AB235: 0 | AC235: 0 | AD235: 0 | AE235: 0
A236: 45005 | B236: H01 | C236: Hotel Atlântico Fortaleza | D236: Fortaleza | E236: Litoral de Fortaleza | F236: 140 | G236: 360 | H236: 182 | I236: 78 | J236: 0.55714286 | K236: 24 | L236: 16 | M236: 153 | N236: 422.53 | O236: 32.4 | P236: 28.4 | Q236: 0 | R236: Segunda | S236: 3 | T236: 79 | U236: 0 | V236: 1 | W236: 0.97389224 | X236: 0.22701082 | Y236: 0 | Z236: 0 | AB236: 0 | AC236: 0 | AD236: 0 | AE236: 0
A237: 45005 | B237: H02 | C237: Resort Dunas do Porto | D237: Aquiraz | E237: Porto das Dunas | F237: 125 | G237: 320 | H237: 143 | I237: 58 | J237: 0.464 | K237: 38 | L237: 28 | M237: 118 | N237: 599.65 | O237: 32.4 | P237: 28.4 | Q237: 0 | R237: Segunda | S237: 3 | T237: 79 | U237: 0 | V237: 1 | W237: 0.97389224 | X237: 0.22701082 | Y237: 0 | Z237: 0 | AB237: 0 | AC237: 0 | AD237: 0 | AE237: 0
A238: 45005 | B238: H03 | C238: Pousada Jericoacoara Azul | D238: Jijoca de Jericoacoara | E238: Litoral Oeste | F238: 85 | G238: 210 | H238: 113 | I238: 48 | J238: 0.56470588 | K238: 15 | L238: 18 | M238: 105 | N238: 485.14 | O238: 32.4 | P238: 28.4 | Q238: 0 | R238: Segunda | S238: 3 | T238: 79 | U238: 0 | V238: 1 | W238: 0.97389224 | X238: 0.22701082 | Y238: 0 | Z238: 0 | AB238: 0 | AC238: 0 | AD238: 0 | AE238: 0
A239: 45006 | B239: H01 | C239: Hotel Atlântico Fortaleza | D239: Fortaleza | E239: Litoral de Fortaleza | F239: 140 | G239: 360 | H239: 176 | I239: 75 | J239: 0.53571429 | K239: 44 | L239: 33 | M239: 152 | N239: 398.29 | O239: 4.8 | P239: 28.1 | Q239: 1 | R239: Terça | S239: 3 | T239: 80 | U239: 0.78183148 | V239: 0.6234898 | W239: 0.97765308 | X239: 0.21022475 | Y239: 0 | Z239: 0 | AB239: 0 | AC239: 0 | AD239: 0 | AE239: 0
A240: 45006 | B240: H02 | C240: Resort Dunas do Porto | D240: Aquiraz | E240: Porto das Dunas | F240: 125 | G240: 320 | H240: 140 | I240: 56 | J240: 0.448 | K240: 35 | L240: 18 | M240: 114 | N240: 578.93 | O240: 4.8 | P240: 28.1 | Q240: 1 | R240: Terça | S240: 3 | T240: 80 | U240: 0.78183148 | V240: 0.6234898 | W240: 0.97765308 | X240: 0.21022475 | Y240: 0 | Z240: 0 | AB240: 0 | AC240: 0 | AD240: 0 | AE240: 0
A241: 45006 | B241: H03 | C241: Pousada Jericoacoara Azul | D241: Jijoca de Jericoacoara | E241: Litoral Oeste | F241: 85 | G241: 210 | H241: 108 | I241: 49 | J241: 0.57647059 | K241: 16 | L241: 17 | M241: 92 | N241: 502.36 | O241: 4.8 | P241: 28.1 | Q241: 1 | R241: Terça | S241: 3 | T241: 80 | U241: 0.78183148 | V241: 0.6234898 | W241: 0.97765308 | X241: 0.21022475 | Y241: 0 | Z241: 0 | AB241: 0 | AC241: 0 | AD241: 0 | AE241: 0
A242: 45007 | B242: H01 | C242: Hotel Atlântico Fortaleza | D242: Fortaleza | E242: Litoral de Fortaleza | F242: 140 | G242: 360 | H242: 176 | I242: 74 | J242: 0.52857143 | K242: 30 | L242: 46 | M242: 147 | N242: 458.7 | O242: 21 | P242: 28.6 | Q242: 2 | R242: Quarta | S242: 3 | T242: 81 | U242: 0.97492791 | V242: -0.22252093 | W242: 0.98112463 | X242: 0.19337647 | Y242: 0 | Z242: 0 | AB242: 0 | AC242: 0 | AD242: 0 | AE242: 0
A243: 45007 | B243: H02 | C243: Resort Dunas do Porto | D243: Aquiraz | E243: Porto das Dunas | F243: 125 | G243: 320 | H243: 148 | I243: 63 | J243: 0.504 | K243: 29 | L243: 41 | M243: 137 | N243: 621.57 | O243: 21 | P243: 28.6 | Q243: 2 | R243: Quarta | S243: 3 | T243: 81 | U243: 0.97492791 | V243: -0.22252093 | W243: 0.98112463 | X243: 0.19337647 | Y243: 0 | Z243: 0 | AB243: 0 | AC243: 0 | AD243: 0 | AE243: 0
A244: 45007 | B244: H03 | C244: Pousada Jericoacoara Azul | D244: Jijoca de Jericoacoara | E244: Litoral Oeste | F244: 85 | G244: 210 | H244: 111 | I244: 48 | J244: 0.56470588 | K244: 31 | L244: 24 | M244: 97 | N244: 511.81 | O244: 21 | P244: 28.6 | Q244: 2 | R244: Quarta | S244: 3 | T244: 81 | U244: 0.97492791 | V244: -0.22252093 | W244: 0.98112463 | X244: 0.19337647 | Y244: 0 | Z244: 0 | AB244: 0 | AC244: 0 | AD244: 0 | AE244: 0
A245: 45008 | B245: H01 | C245: Hotel Atlântico Fortaleza | D245: Fortaleza | E245: Litoral de Fortaleza | F245: 140 | G245: 360 | H245: 160 | I245: 70 | J245: 0.5 | K245: 43 | L245: 17 | M245: 142 | N245: 445.43 | O245: 14.3 | P245: 26.1 | Q245: 3 | R245: Quinta | S245: 3 | T245: 82 | U245: 0.43388374 | V245: -0.90096887 | W245: 0.98430584 | X245: 0.17647097 | Y245: 0 | Z245: 0 | AB245: 0 | AC245: 0 | AD245: 0 | AE245: 0
A246: 45008 | B246: H02 | C246: Resort Dunas do Porto | D246: Aquiraz | E246: Porto das Dunas | F246: 125 | G246: 320 | H246: 125 | I246: 55 | J246: 0.44 | K246: 25 | L246: 25 | M246: 101 | N246: 658.69 | O246: 14.3 | P246: 26.1 | Q246: 3 | R246: Quinta | S246: 3 | T246: 82 | U246: 0.43388374 | V246: -0.90096887 | W246: 0.98430584 | X246: 0.17647097 | Y246: 0 | Z246: 0 | AB246: 0 | AC246: 0 | AD246: 0 | AE246: 0
A247: 45008 | B247: H03 | C247: Pousada Jericoacoara Azul | D247: Jijoca de Jericoacoara | E247: Litoral Oeste | F247: 85 | G247: 210 | H247: 100 | I247: 44 | J247: 0.51764706 | K247: 16 | L247: 17 | M247: 85 | N247: 499.22 | O247: 14.3 | P247: 26.1 | Q247: 3 | R247: Quinta | S247: 3 | T247: 82 | U247: 0.43388374 | V247: -0.90096887 | W247: 0.98430584 | X247: 0.17647097 | Y247: 0 | Z247: 0 | AB247: 0 | AC247: 0 | AD247: 0 | AE247: 0
... A250: 45009 | B250: H03 | C250: Pousada Jericoacoara Azul | D250: Jijoca de Jericoacoara | E250: Litoral Oeste | F250: 85 | G250: 210 | H250: 109 | I250: 51 | J250: 0.6 | K250: 14 | L250: 27 | M250: 99 | N250: 548.14 | O250: 15.6 | P250: 28 | Q250: 4 | R250: Sexta | S250: 3 | T250: 83 | U250: -0.43388374 | V250: -0.90096887 | W250: 0.98719579 | X250: 0.15951325 | Y250: 0 | Z250: 0 | AB250: 0 | AC250: 0 | AD250: 0 | AE250: 0
A251: 45010 | B251: H01 | C251: Hotel Atlântico Fortaleza | D251: Fortaleza | E251: Litoral de Fortaleza | F251: 140 | G251: 360 | H251: 226 | I251: 96 | J251: 0.68571429 | K251: 39 | L251: 33 | M251: 209 | N251: 497.39 | O251: 2.1 | P251: 27.3 | Q251: 5 | R251: Sábado | S251: 3 | T251: 84 | U251: -0.97492791 | V251: -0.22252093 | W251: 0.9897936 | X251: 0.14250833 | Y251: 1 | Z251: 1 | AA251: Data Magna do Ceará | AB251: 0 | AC251: 0 | AD251: 0 | AE251: 0
A252: 45010 | B252: H02 | C252: Resort Dunas do Porto | D252: Aquiraz | E252: Porto das Dunas | F252: 125 | G252: 320 | H252: 196 | I252: 82 | J252: 0.656 | K252: 49 | L252: 29 | M252: 179 | N252: 648.2 | O252: 2.1 | P252: 27.3 | Q252: 5 | R252: Sábado | S252: 3 | T252: 84 | U252: -0.97492791 | V252: -0.22252093 | W252: 0.9897936 | X252: 0.14250833 | Y252: 1 | Z252: 1 | AA252: Data Magna do Ceará | AB252: 0 | AC252: 0 | AD252: 0 | AE252: 0
A253: 45010 | B253: H03 | C253: Pousada Jericoacoara Azul | D253: Jijoca de Jericoacoara | E253: Litoral Oeste | F253: 85 | G253: 210 | H253: 148 | I253: 69 | J253: 0.81176471 | K253: 37 | L253: 19 | M253: 135 | N253: 618.73 | O253: 2.1 | P253: 27.3 | Q253: 5 | R253: Sábado | S253: 3 | T253: 84 | U253: -0.97492791 | V253: -0.22252093 | W253: 0.9897936 | X253: 0.14250833 | Y253: 1 | Z253: 1 | AA253: Data Magna do Ceará | AB253: 0 | AC253: 0 | AD253: 0 | AE253: 0
A254: 45011 | B254: H01 | C254: Hotel Atlântico Fortaleza | D254: Fortaleza | E254: Litoral de Fortaleza | F254: 140 | G254: 360 | H254: 203 | I254: 87 | J254: 0.62142857 | K254: 26 | L254: 48 | M254: 167 | N254: 458.67 | O254: 6.9 | P254: 27.9 | Q254: 6 | R254: Domingo | S254: 3 | T254: 85 | U254: -0.78183148 | V254: 0.6234898 | W254: 0.99209852 | X254: 0.12546123 | Y254: 1 | Z254: 0 | AB254: 0 | AC254: 0 | AD254: 0 | AE254: 0
A255: 45011 | B255: H02 | C255: Resort Dunas do Porto | D255: Aquiraz | E255: Porto das Dunas | F255: 125 | G255: 320 | H255: 180 | I255: 73 | J255: 0.584 | K255: 26 | L255: 40 | M255: 147 | N255: 674.98 | O255: 6.9 | P255: 27.9 | Q255: 6 | R255: Domingo | S255: 3 | T255: 85 | U255: -0.78183148 | V255: 0.6234898 | W255: 0.99209852 | X255: 0.12546123 | Y255: 1 | Z255: 0 | AB255: 0 | AC255: 0 | AD255: 0 | AE255: 0
A256: 45011 | B256: H03 | C256: Pousada Jericoacoara Azul | D256: Jijoca de Jericoacoara | E256: Litoral Oeste | F256: 85 | G256: 210 | H256: 138 | I256: 61 | J256: 0.71764706 | K256: 20 | L256: 23 | M256: 120 | N256: 589.59 | O256: 6.9 | P256: 27.9 | Q256: 6 | R256: Domingo | S256: 3 | T256: 85 | U256: -0.78183148 | V256: 0.6234898 | W256: 0.99209852 | X256: 0.12546123 | Y256: 1 | Z256: 0 | AB256: 0 | AC256: 0 | AD256: 0 | AE256: 0
A257: 45012 | B257: H01 | C257: Hotel Atlântico Fortaleza | D257: Fortaleza | E257: Litoral de Fortaleza | F257: 140 | G257: 360 | H257: 192 | I257: 82 | J257: 0.58571429 | K257: 35 | L257: 45 | M257: 177 | N257: 413.48 | O257: 12.1 | P257: 26.6 | Q257: 0 | R257: Segunda | S257: 3 | T257: 86 | U257: 0 | V257: 1 | W257: 0.99410986 | X257: 0.10837701 | Y257: 0 | Z257: 0 | AB257: 0 | AC257: 0 | AD257: 0 | AE257: 0
...

Sheet Dicionario
A1: Variável | B1: Descrição | C1: Uso no estudo / observação
A2: Data | B2: Data de referência da observação diária. | C2: Índice temporal; manter ordenação cronológica.
A3: Hotel_ID / Hotel | B3: Identificador e nome do estabelecimento. | C3: Permite treinar uma RNN por hotel ou uma RNN global.
A4: Hospedes_Hospedados | B4: Quantidade de hóspedes presentes no hotel na data. | C4: Variável-alvo (y) recomendada para previsão de carga operacional.
A5: Reservas_Confirmadas_D14 | B5: Hóspedes associados a reservas registradas 14 dias antes da data de hospedagem. | C5: Preditor exógeno simulado; é conhecido com antecedência. Deve ser tratado conforme o horizonte de previsão.
A6: Hospedes_Checkin | B6: Quantidade estimada de hóspedes que realizaram check-in no dia. | C6: Indicador auxiliar para recepção e processos de entrada; não usar como preditor contemporâneo se desconhecido na previsão.
A7: Hospedes_Checkout | B7: Quantidade estimada de hóspedes que realizaram check-out no dia. | C7: Indicador auxiliar para recepção e arrumação; não usar como preditor contemporâneo se desconhecido na previsão.
A8: Quartos_Ocupados | B8: Quantidade de quartos ocupados. | C8: Indicador para dimensionamento de governança/limpeza; derivado da demanda simulada.
A9: Taxa_Ocupacao | B9: Quartos ocupados divididos pelo total de quartos. | C9: Indicador de utilização da capacidade; derivado, portanto não deve ser usado junto com o alvo do mesmo dia.
A10: Diaria_Media_R$ | B10: Tarifa média diária simulada. | C10: Variável de contexto comercial; usar como preditor somente se conhecida no instante da previsão.
A11: Chuva_mm / Temperatura_Max_C | B11: Condições climáticas diárias simuladas. | C11: Observações sintéticas; para previsão futura, substituir por previsão meteorológica ou excluir.
A12: Dia_Semana / Mes / Dia_Ano | B12: Componentes de calendário. | C12: Podem ser codificados por seno/cosseno ou one-hot encoding.
... A19: Evento_Local_Simulado | B19: Marcador de datas de eventos turísticos ilustrativos. | C19: Não representa calendário oficial de eventos.

Sheet Painel
A1: PAINEL — DEMANDA HOTELEIRA SINTÉTICA | LITORAL DO CEARÁ | H1: Mês | I1: Hotel H01 | J1: Hotel H02 | K1: Hotel H03
H2: jan/23 | I2: 231.8 | J2: 231 | K2: 163.6
A3: Hotel_ID | B3: Hotel | C3: Média hóspedes/dia | D3: Mínimo diário | E3: Máximo diário | F3: Total de hóspedes-dia | H3: fev/23 | I3: 204.7 | J3: 182.8 | K3: 130.6
A4: H01 | B4: Hotel Atlântico Fortaleza | C4: =AVERAGEIF(Dados_Longos!$B$2:$B$3289,A4,Dados_Longos!$H$2:$H$3289) -> 202.58303 | D4: =_xlfn.MINIFS(Dados_Longos!$H$2:$H$3289,Dados_Longos!$B$2:$B$3289,A4) -> 145 | E4: =_xlfn.MAXIFS(Dados_Longos!$H$2:$H$3289,Dados_Longos!$B$2:$B$3289,A4) -> 303 | F4: =SUMIF(Dados_Longos!$B$2:$B$3289,A4,Dados_Longos!$H$2:$H$3289) -> 222031 | H4: mar/23 | I4: 184.7 | J4: 160.6 | K4: 117.8
A5: H02 | B5: Resort Dunas do Porto | C5: =AVERAGEIF(Dados_Longos!$B$2:$B$3289,A5,Dados_Longos!$H$2:$H$3289) -> 186.51642 | D5: =_xlfn.MINIFS(Dados_Longos!$H$2:$H$3289,Dados_Longos!$B$2:$B$3289,A5) -> 119 | E5: =_xlfn.MAXIFS(Dados_Longos!$H$2:$H$3289,Dados_Longos!$B$2:$B$3289,A5) -> 294 | F5: =SUMIF(Dados_Longos!$B$2:$B$3289,A5,Dados_Longos!$H$2:$H$3289) -> 204422 | H5: abr/23 | I5: 182.9 | J5: 162.3 | K5: 117.5
A6: H03 | B6: Pousada Jericoacoara Azul | C6: =AVERAGEIF(Dados_Longos!$B$2:$B$3289,A6,Dados_Longos!$H$2:$H$3289) -> 133.62774 | D6: =_xlfn.MINIFS(Dados_Longos!$H$2:$H$3289,Dados_Longos!$B$2:$B$3289,A6) -> 83 | E6: =_xlfn.MAXIFS(Dados_Longos!$H$2:$H$3289,Dados_Longos!$B$2:$B$3289,A6) -> 193 | F6: =SUMIF(Dados_Longos!$B$2:$B$3289,A6,Dados_Longos!$H$2:$H$3289) -> 146456 | H6: mai/23 | I6: 182.6 | J6: 159.9 | K6: 117.1
H7: jun/23 | I7: 195 | J7: 170.9 | K7: 122.9
H8: jul/23 | I8: 234.2 | J8: 232.5 | K8: 159.5
A9: Observação | B9: Os valores do painel são calculados a partir de Dados_Longos. Dados sintéticos, não oficiais. | H9: ago/23 | I9: 205.7 | J9: 176.6 | K9: 127.3
H10: set/23 | I10: 184.9 | J10: 163.7 | K10: 119.4
H11: out/23 | I11: 178.3 | J11: 159.1 | K11: 116.9
H12: nov/23 | I12: 187.7 | J12: 166.1 | K12: 121.6
H13: dez/23 | I13: 219.5 | J13: 212.4 | K13: 148.8
H14: jan/24 | I14: 233.9 | J14: 235.2 | K14: 165.8
H15: fev/24 | I15: 207 | J15: 183.8 | K15: 133
H16: mar/24 | I16: 192.8 | J16: 172.4 | K16: 121.6
H17: abr/24 | I17: 184.4 | J17: 163.4 | K17: 118
H18: mai/24 | I18: 182.2 | J18: 164.1 | K18: 118.3
H19: jun/24 | I19: 202.5 | J19: 176.8 | K19: 129.7
H20: jul/24 | I20: 233 | J20: 234.6 | K20: 166.5
H21: ago/24 | I21: 204.4 | J21: 181.1 | K21: 134
... H37: dez/25 | I37: 226.4 | J37: 219.8 | K37: 152
